
##严格对齐

##遇到结果是pemission denied，在执行命令前加sudo

##homebrew安装python的情况如下图所示


##为python3安装包使用 pip3命令
If it's Python 3, a solution would be pip3 install requests


##执行时出现了错误：SyntaxError: Non-ASCII character '\xe6'
SyntaxError: Non-ASCII character '\xe6' in file 打印日期.py on line 1, but no encoding declared; see http://www.python.org/peps/pep-0263.html for details

因为Python在默认状态下不支持源文件中的编码所致。解决方案有如下三种：
一、在文件头部添加如下注释码：
 # coding=<encoding name> 例如，可添加# coding=utf-8  ，**并且只有放在整个文件的第一行才有效**
错误的写法：
```
# @file evaluate.py
# @brief enroll & evaluate
# @author libowei,378632668@qq.com
# @version 0.2.00
# @date 2016-9-3


# -*- coding:utf8 -*-
```

正确的写法：
```
# -*- coding:utf8 -*-

# @file evaluate.py
# @brief enroll & evaluate
# @author libowei,378632668@qq.com
# @version 0.2.00
# @date 2016-9-3
```

二、在文件头部添加如下两行注释码：
```
#!/usr/bin/python
# -*- coding: <encoding name> -*- 例如，可添加# -*- coding: utf-8 -*-
```
三、在文件头部添加如下两行注释码：
```
 #!/usr/bin/python
# vim: set fileencoding=<encoding name> : 例如，可添加# vim: set fileencoding=utf-8 :
```

##下载课件的过程中报错
开始下载课件......
开始下载cdn-p2p.pdf...
开始下载FIA_v4.pdf...
开始下载FIA_v4.pptx...
开始下载QoS（基础知识）.pdf...
开始下载QoS（基础知识）.pptx...
开始下载QoS（案例）.pdf...
开始下载QoS（案例）.pptx...
开始下载专题-TCP优化.pdf...
开始下载专题-路由器设计.pdf...
开始下载第14讲 路由器-2016秋.pptx...
Traceback (most recent call last):
  File "/usr/local/lib/python3.5/site-packages/requests/packages/urllib3/response.py", line 298, in _error_catcher
    yield
  File "/usr/local/lib/python3.5/site-packages/requests/packages/urllib3/response.py", line 380, in read
    data = self._fp.read(amt)
  File "/usr/local/Cellar/python3/3.5.1/Frameworks/Python.framework/Versions/3.5/lib/python3.5/http/client.py", line 433, in read
    n = self.readinto(b)
  File "/usr/local/Cellar/python3/3.5.1/Frameworks/Python.framework/Versions/3.5/lib/python3.5/http/client.py", line 473, in readinto
    n = self.fp.readinto(b)
  File "/usr/local/Cellar/python3/3.5.1/Frameworks/Python.framework/Versions/3.5/lib/python3.5/socket.py", line 575, in readinto
    return self._sock.recv_into(b)
ConnectionResetError: [Errno 54] Connection reset by peer

During handling of the above exception, another exception occurred:

Traceback (most recent call last):
  File "/usr/local/lib/python3.5/site-packages/requests/models.py", line 694, in generate
    for chunk in self.raw.stream(chunk_size, decode_content=True):
  File "/usr/local/lib/python3.5/site-packages/requests/packages/urllib3/response.py", line 432, in stream
    data = self.read(amt=amt, decode_content=decode_content)
  File "/usr/local/lib/python3.5/site-packages/requests/packages/urllib3/response.py", line 397, in read
    raise IncompleteRead(self._fp_bytes_read, self.length_remaining)
  File "/usr/local/Cellar/python3/3.5.1/Frameworks/Python.framework/Versions/3.5/lib/python3.5/contextlib.py", line 77, in __exit__
    self.gen.throw(type, value, traceback)
  File "/usr/local/lib/python3.5/site-packages/requests/packages/urllib3/response.py", line 316, in _error_catcher
    raise ProtocolError('Connection broken: %r' % e, e)
requests.packages.urllib3.exceptions.ProtocolError: ("Connection broken: ConnectionResetError(54, 'Connection reset by peer')", ConnectionResetError(54, 'Connection reset by peer'))

During handling of the above exception, another exception occurred:

Traceback (most recent call last):
  File "download.py", line 147, in <module>
    getClass(c[1], url, session, None)
  File "download.py", line 58, in getClass
    download(resUrl, resName, currentClass, session)
  File "download.py", line 26, in download
    s = session.get(url)
  File "/usr/local/lib/python3.5/site-packages/requests/sessions.py", line 501, in get
    return self.request('GET', url, **kwargs)
  File "/usr/local/lib/python3.5/site-packages/requests/sessions.py", line 488, in request
    resp = self.send(prep, **send_kwargs)
  File "/usr/local/lib/python3.5/site-packages/requests/sessions.py", line 641, in send
    r.content
  File "/usr/local/lib/python3.5/site-packages/requests/models.py", line 772, in content
    self._content = bytes().join(self.iter_content(CONTENT_CHUNK_SIZE)) or bytes()
  File "/usr/local/lib/python3.5/site-packages/requests/models.py", line 697, in generate
    raise ChunkedEncodingError(e)
requests.exceptions.ChunkedEncodingError: ("Connection broken: ConnectionResetError(54, 'Connection reset by peer')", ConnectionResetError(54, 'Connection reset by peer'))
MacdeMacBook-Pro-3:ucas_course_tool mac$
